Workbook

Sheet Tarifario completo
B2: LISTA DE PRECIOS | F2: 26.09 | K2: Vigencia: | L2: 46266
B3: BANDA | C3: As/Sim | D3: Hogar/ Corp | E3: Fib/Rad | F3: Mb | G3: Cant Abonados ANTERIOR | H3: Cant Abonados ACTUAL | I3: Cargo Inst (bonificado si Deb Aut T/C) | J3: Abono Mensual CON IVA, ANTERIOR | K3: AUMENTO | L3: Abono Mensual CON IVA, aumento de esta versión | M3: OBSERVACIONES
B4: RESIDENCIALES | G4: 46218 | H4: 46253 | O4: Actual | P4: Futuro | Q4: Diferencia
B5: MUNDIAL F99 (EDICIÓN LIMITADA) SÓLO LO INFORMA VENTAS | C5: S | D5: H | E5: F | F5: 50 | G5: 69 | H5: 68 | I5: 20000 | J5: 25152.233 | K5: 0.022 | L5: =+J5*(1+K5) -> 25705.582 | M5: =+H5/G5-1 -> -0.014492754 | O5: =+J5*H5 -> 1710351.8 | P5: =+L5*H5 -> 1747979.6 | Q5: =+P5-O5 -> 37627.741
B6: HOME F111 | C6: A | D6: H | E6: F | F6: 75 / 10 | G6: 4717 | H6: 4735 | I6: 20000 | J6: 25152.313 | K6: 0.022 | L6: =+J6*(1+K6) -> 25705.664 | M6: =+H6/G6-1 -> 0.0038159847 | O6: =+J6*H6 -> 1.190962e+08 | P6: =+L6*H6 -> 1.2171632e+08 | Q6: =+P6-O6 -> 2620116.4
B7: FAST F121 | C7: A | D7: H | E7: F | F7: 150 / 15 | G7: 1292 | H7: 1288 | I7: 20000 | J7: 31058.057 | K7: 0.021 | L7: =+J7*(1+K7) -> 31710.276 | M7: =+H7/G7-1 -> -0.0030959752 | O7: =+J7*H7 -> 40002778 | P7: =+L7*H7 -> 40842836 | Q7: =+P7-O7 -> 840058.33
B8: POWER F131 | C8: A | D8: H | E8: F | F8: 300 / 30 | G8: 2099 | H8: 2198 | I8: 20000 | J8: 32205.449 | K8: =+K7 -> 0.021 | L8: =+J8*(1+K8) -> 32881.764 | M8: =+H8/G8-1 -> 0.047165317 | O8: =+J8*H8 -> 70787578 | P8: =+L8*H8 -> 72274117 | Q8: =+P8-O8 -> 1486539.1
B9: GAMER F141 | C9: S | D9: H | E9: F | F9: 300 M | G9: 334 | H9: 336 | I9: 20000 | J9: 41980.687 | K9: =+K8 -> 0.021 | L9: =+J9*(1+K9) -> 42862.281 | M9: =+H9/G9-1 -> 0.005988024 | O9: =+J9*H9 -> 14105511 | P9: =+L9*H9 -> 14401726 | Q9: =+P9-O9 -> 296215.73
B10: WORKER F151 | C10: S | D10: H | E10: F | F10: 200 M | G10: 98 | H10: 105 | I10: 20000 | J10: 45798.848 | K10: =+K9 -> 0.021 | L10: =+J10*(1+K10) -> 46760.624 | M10: =+H10/G10-1 -> 0.071428571 | O10: =+J10*H10 -> 4808879.1 | P10: =+L10*H10 -> 4909865.5 | Q10: =+P10-O10 -> 100986.46
B11: MAX F161 (NUEVO) | C11: S | D11: H | E11: F | F11: 1000 M | G11: 24 | H11: 25 | I11: 20000 | J11: 54688.878 | K11: =+K10 -> 0.021 | L11: =+J11*(1+K11) -> 55837.344 | M11: =+H11/G11-1 -> 0.041666667 | O11: =+J11*H11 -> 1367221.9 | P11: =+L11*H11 -> 1395933.6 | Q11: =+P11-O11 -> 28711.661
B12: SistaFLEX (domicilio adicional) | G12: 50 | H12: 52 | J12: 14498.84 | K12: 0 | L12: =+J12*(1+K12) -> 14498.84 | M12: ACTUALIZAR en DICIEMBRE 2026 Se decide mantener este precio por CUATRIMESTRE para no modificar los flyers | O12: =+J12*H12 -> 753939.68 | P12: =+L12*H12 -> 753939.68 | Q12: =+P12-O12 -> 0
B13: ANTINA PLAY + | G13: =413+246 -> 659 | H13: 647 | J13: 19890 | K13: =+L13/J13-1 -> 0 | L13: 19890 | O13: =+J13*H13 -> 12868830 | P13: =+L13*H13 -> 12868830 | Q13: =+P13-O13 -> 0
B14: Básico + Cine | G14: 5 | H14: 5 | J14: 45950 | K14: =+L14/J14-1 -> 0 | L14: 45950 | O14: =+J14*H14 -> 229750 | P14: =+L14*H14 -> 229750 | Q14: =+P14-O14 -> 0
B15: Pack Fútbol (Antina) | G15: 156 | H15: 161 | J15: 29500 | K15: =+L15/J15-1 -> 0 | L15: 29500 | O15: =+J15*H15 -> 4749500 | P15: =+L15*H15 -> 4749500 | Q15: =+P15-O15 -> 0
B16: DGO Full | G16: 136 | H16: 112 | J16: 35050 | K16: =+L16/J16-1 -> 0 | L16: 35050 | O16: =+J16*H16 -> 3925600 | P16: =+L16*H16 -> 3925600 | Q16: =+P16-O16 -> 0
B17: DGo Fútbol total (Full + Dsports + Amazon + Fútbol) NUEVO | G17: 1 | H17: 0 | J17: 39300 | K17: =+L17/J17-1 -> 0 | L17: 39300 | O17: =+J17*H17 -> 0 | P17: =+L17*H17 -> 0 | Q17: =+P17-O17 -> 0
B18: Pack Fútbol (DGo) | G18: 50 | H18: 62 | J18: 25610 | K18: =+L18/J18-1 -> 0 | L18: 25610 | O18: =+J18*H18 -> 1587820 | P18: =+L18*H18 -> 1587820 | Q18: =+P18-O18 -> 0
B19: PARAMOUNT + (Dgo) | G19: 1 | H19: 1 | J19: 9135 | K19: =+L19/J19-1 -> 0 | L19: 9135 | O19: =+J19*H19 -> 9135 | P19: =+L19*H19 -> 9135 | Q19: =+P19-O19 -> 0
B20: UNIVERSAL (DGo) | G20: 1 | H20: 2 | J20: 15120 | K20: =+L20/J20-1 -> 0 | L20: 15120 | O20: =+J20*H20 -> 30240 | P20: =+L20*H20 -> 30240 | Q20: =+P20-O20 -> 0
B21: GIGARED Básico | G21: 165 | H21: 166 | J21: 13100 | K21: =+L21/J21-1 -> 0 | L21: 13100 | O21: =+J21*H21 -> 2174600 | P21: =+L21*H21 -> 2174600 | Q21: =+P21-O21 -> 0
B22: Pack Fútbol (Gigared) | G22: 15 | H22: 17 | J22: 25610 | K22: =+L22/J22-1 -> 0 | L22: 25610 | O22: =+J22*H22 -> 435370 | P22: =+L22*H22 -> 435370 | Q22: =+P22-O22 -> 0
B23: LINEA VIP 55-011 | G23: 1 | H23: 1 | J23: 19501.255 | K23: 0.1 | L23: =+J23*(1+K23) -> 21451.381 | M23: Se empieza una rampa para levantar este valor, que está bajo | O23: =+J23*H23 -> 19501.255 | P23: =+L23*H23 -> 21451.381 | Q23: =+P23-O23 -> 1950.1255
B24: LINEA VIP 56-221 | G24: 258 | H24: 249 | J24: 9971.6034 | K24: 0.021 | L24: =+J24*(1+K24) -> 10181.007 | M24: Se empieza una rampa para levantar este valor, que está bajo | O24: =+J24*H24 -> 2482929.2 | P24: =+L24*H24 -> 2535070.8 | Q24: =+P24-O24 -> 52141.514
B25: PABXIP VIRTUAL.BASICA (****) | G25: 1 | H25: 1 | I25: =150*1430 -> 214500 | J25: 37887.7 | K25: =+K11 -> 0.021 | L25: =+J25*(1+K25) -> 38683.342 | M25: 1 línea + 4 internos No incluye equipos EL cargo de conexión no se bonifica por adhesión al débito automatico | O25: =+J25*H25 -> 37887.7 | P25: =+L25*H25 -> 38683.342 | Q25: =+P25-O25 -> 795.64171
B26: Línea Adicional a PABXIP | G26: 1 | H26: 1 | J26: 7577.5401 | K26: =+K25 -> 0.021 | L26: =+J26*(1+K26) -> 7736.6684 | M26: NUEVO, A PARTIR DE ABRIL 2026 | O26: =+J26*H26 -> 7577.5401 | P26: =+L26*H26 -> 7736.6684 | Q26: =+P26-O26 -> 159.12834
B27: Internos adicionales a PABXIP | G27: 0 | H27: 0 | J27: 3788.77 | K27: =+K26 -> 0.021 | L27: =+J27*(1+K27) -> 3868.3342 | M27: NUEVO, A PARTIR DE ABRIL 2026 | O27: =+J27*H27 -> 0 | P27: =+L27*H27 -> 0 | Q27: =+P27-O27 -> 0
B28: SPRINT Banda 74 | C28: A | D28: H | E28: R | F28: 6/3 M | G28: 56 | H28: 43 | I28: 50000 | J28: 44931.045 | K28: =+K27 -> 0.021 | L28: =+J28*(1+K28) -> 45874.597 | O28: =+J28*H28 -> 1932034.9 | P28: =+L28*H28 -> 1972607.7 | Q28: =+P28-O28 -> 40572.734
B29: SPRINT Banda 77 (*) | C29: A | D29: H | E29: R | F29: 10/5 M | G29: 20 | H29: 17 | I29: 50000 | J29: 50618.209 | K29: =+K28 -> 0.021 | L29: =+J29*(1+K29) -> 51681.192 | M29: Villa Castells + Arco Iris | O29: =+J29*H29 -> 860509.56 | P29: =+L29*H29 -> 878580.26 | Q29: =+P29-O29 -> 18070.701
B30: EMPRESAS
B31: SPRINT Banda F101 | C31: S | D31: C | E31: F | F31: 200 M | G31: 40 | H31: 40 | I31: 20000 | J31: 52980.462 | K31: =+K29 -> 0.021 | L31: =+J31*(1+K31) -> 54093.052 | O31: =+J31*H31 -> 2119218.5 | P31: =+L31*H31 -> 2163722.1 | Q31: =+P31-O31 -> 44503.588
B32: SPRINT Banda F103 | C32: S | D32: C | E32: F | F32: 400 M | G32: 3 | H32: 3 | I32: 20000 | J32: 101018.3 | K32: =+K31 -> 0.021 | L32: =+J32*(1+K32) -> 103139.68 | O32: =+J32*H32 -> 303054.89 | P32: =+L32*H32 -> 309419.04 | Q32: =+P32-O32 -> 6364.1526
B33: SPRINT Banda F104 | C33: S | D33: C | E33: F | F33: 600 M | G33: 16 | H33: 16 | I33: 20000 | J33: 112878.95 | K33: =+K32 -> 0.021 | L33: =+J33*(1+K33) -> 115249.4 | O33: =+J33*H33 -> 1806063.2 | P33: =+L33*H33 -> 1843990.5 | Q33: =+P33-O33 -> 37927.326
B34: SPRINT Banda F105 | C34: S | D34: C | E34: F | F34: 900 M | G34: 0 | H34: 0 | I34: 20000 | J34: 138103.23 | K34: =+K33 -> 0.021 | L34: =+J34*(1+K34) -> 141003.39 | O34: =+J34*H34 -> 0 | P34: =+L34*H34 -> 0 | Q34: =+P34-O34 -> 0
B35: SPRINT Banda 94 | C35: S | D35: C | E35: R | F35: 20 M | G35: 30 | H35: 27 | I35: 50000 | J35: 58992.66 | K35: =+K33 -> 0.021 | L35: =+J35*(1+K35) -> 60231.506 | O35: =+J35*H35 -> 1592801.8 | P35: =+L35*H35 -> 1626250.7 | Q35: =+P35-O35 -> 33448.838
B36: ESPECIALES | O36: =SUM(O5:O35) -> 2.8980488e+08 | P36: =SUM(P5:P35) -> 2.9545107e+08 | Q36: =SUM(Q5:Q35) -> 5646189.2
B37: Cableado por dispositivo HASTA 10 metros | I37: 40000
B38: Cableado METRO ADICIONAL | I38: 4000
B39: Tareas a domicilio (precio por hora) | I39: 40000
B40: Traslado de Servicio RADIO | I40: 30000
B41: Traslado de Servicio FIBRA | I41: 16500
...

Sheet Tarifas Web
B1: ESTO ES LO QUE SE PUBLICA POR LA WEB www.sista.ar/tarifas
B5: =+'Tarifario completo'!L2 -> 46266 | C5: Sin impuestos nacionales | D5: Abono Mensual
B6: =+'Tarifario completo'!B6 -> HOME F111 | C6: =+D6/(1+$D$42) -> 21244.35 | D6: =+'Tarifario completo'!L6 -> 25705.664
B7: =+'Tarifario completo'!B7 -> FAST F121 | C7: =+D7/(1+$D$42) -> 26206.84 | D7: =+'Tarifario completo'!L7 -> 31710.276
B8: =+'Tarifario completo'!B8 -> POWER F131 | C8: =+D8/(1+$D$42) -> 27175.011 | D8: =+'Tarifario completo'!L8 -> 32881.764
B9: =+'Tarifario completo'!B9 -> GAMER F141 | C9: =+D9/(1+$D$42) -> 35423.373 | D9: =+'Tarifario completo'!L9 -> 42862.281
B10: =+'Tarifario completo'!B10 -> WORKER F151 | C10: =+D10/(1+$D$42) -> 38645.144 | D10: =+'Tarifario completo'!L10 -> 46760.624
B11: =+'Tarifario completo'!B11 -> MAX F161 (NUEVO) | C11: =+D11/(1+$D$42) -> 46146.566 | D11: =+'Tarifario completo'!L11 -> 55837.344
B12: =+'Tarifario completo'!B12 -> SistaFLEX (domicilio adicional) | C12: =+D12/(1+$D$42) -> 11982.512 | D12: =+'Tarifario completo'!L12 -> 14498.84
B13: =+'Tarifario completo'!B13 -> ANTINA PLAY + | C13: =+D13/(1+$D$42) -> 16438.017 | D13: =+'Tarifario completo'!L13 -> 19890
B14: =+'Tarifario completo'!B14 -> Básico + Cine | C14: =+D14/(1+$D$42) -> 37975.207 | D14: =+'Tarifario completo'!L14 -> 45950
B15: =+'Tarifario completo'!B15 -> Pack Fútbol (Antina) | C15: =+D15/(1+$D$42) -> 24380.165 | D15: =+'Tarifario completo'!L15 -> 29500
B16: =+'Tarifario completo'!B16 -> DGO Full | C16: =+D16/(1+$D$42) -> 28966.942 | D16: =+'Tarifario completo'!L16 -> 35050
B17: =+'Tarifario completo'!B17 -> DGo Fútbol total (Full + Dsports + Amazon + Fútbol) NUEVO | C17: =+D17/(1+$D$42) -> 32479.339 | D17: =+'Tarifario completo'!L17 -> 39300
... B29: =+'Tarifario completo'!B29 -> SPRINT Banda 77 (*) | C29: =+D29/(1+$D$42) -> 42711.729 | D29: =+'Tarifario completo'!L29 -> 51681.192
B30: =+'Tarifario completo'!B31 -> SPRINT Banda F101 | C30: =+D30/(1+$D$42) -> 44705.001 | D30: =+'Tarifario completo'!L31 -> 54093.052
B31: =+'Tarifario completo'!B32 -> SPRINT Banda F103 | C31: =+D31/(1+$D$42) -> 85239.405 | D31: =+'Tarifario completo'!L32 -> 103139.68
B32: =+'Tarifario completo'!B33 -> SPRINT Banda F104 | C32: =+D32/(1+$D$42) -> 95247.442 | D32: =+'Tarifario completo'!L33 -> 115249.4
B33: =+'Tarifario completo'!B35 -> SPRINT Banda 94 | C33: =+D33/(1+$D$42) -> 49778.104 | D33: =+'Tarifario completo'!L35 -> 60231.506
D34: =+'Tarifario completo'!F2 -> 26.09
B36: Copiar rango B5:C34, pegarlo en Word, guardarlo como "página web filtrada" al resultante en htm renombrarlo como "index.php" (así en minúsculas) Revisar tamaño de tabla, y si hace falta achicar la fuente del texto
B38: Configurar Word en "Avanzadas" "Opciones Web" "Codificación" "Guardar este documento como…" poner "Cirílico (DOS)
C40: IVA | D40: 0.21
C41: Otros impuestos nacionales | D41: 0
C42: Total alícuota impuestos nacionales | D42: =SUM(D40:D41) -> 0.21

Sheet Precios Mostrador
B2: =+'Tarifario completo'!F2 -> 26.09 | H2: Vigencia desde | I2: =+'Tarifario completo'!L2 -> 46266
B3: SPRINT - PLANES Y SERVICIOS DISPONIBLES | F3: Cargo Inicial Única Vez (bonificado con débito automático en TC) | H3: Abono Mensual
B4: Banda | C4: Servicio | E4: Megas | F4: sin inpuestos nacionales | G4: Precio final | H4: sin inpuestos nacionales | I4: Precio final
B5: =+'Tarifario completo'!B5 -> MUNDIAL F99 (EDICIÓN LIMITADA) SÓLO LO INFORMA VENTAS | C5: =+'Tarifario completo'!C5 -> S | D5: =+'Tarifario completo'!E5 -> F | E5: =+'Tarifario completo'!F5 -> 50 | F5: =+G5/1.21 -> 16528.926 | G5: =+'Tarifario completo'!I5 -> 20000 | H5: =+I5/1.21 -> 21244.283 | I5: =+'Tarifario completo'!L5 -> 25705.582
B6: =+'Tarifario completo'!B6 -> HOME F111 | C6: =+'Tarifario completo'!C6 -> A | D6: =+'Tarifario completo'!E6 -> F | E6: =+'Tarifario completo'!F6 -> 75 / 10 | F6: =+G6/1.21 -> 16528.926 | G6: =+'Tarifario completo'!I6 -> 20000 | H6: =+I6/1.21 -> 21244.35 | I6: =+'Tarifario completo'!L6 -> 25705.664
B7: =+'Tarifario completo'!B7 -> FAST F121 | C7: =+'Tarifario completo'!C7 -> A | D7: =+'Tarifario completo'!E7 -> F | E7: =+'Tarifario completo'!F7 -> 150 / 15 | F7: =+G7/1.21 -> 16528.926 | G7: =+'Tarifario completo'!I7 -> 20000 | H7: =+I7/1.21 -> 26206.84 | I7: =+'Tarifario completo'!L7 -> 31710.276
B8: =+'Tarifario completo'!B8 -> POWER F131 | C8: =+'Tarifario completo'!C8 -> A | D8: =+'Tarifario completo'!E8 -> F | E8: =+'Tarifario completo'!F8 -> 300 / 30 | F8: =+G8/1.21 -> 16528.926 | G8: =+'Tarifario completo'!I8 -> 20000 | H8: =+I8/1.21 -> 27175.011 | I8: =+'Tarifario completo'!L8 -> 32881.764
B9: =+'Tarifario completo'!B9 -> GAMER F141 | C9: =+'Tarifario completo'!C9 -> S | D9: =+'Tarifario completo'!E9 -> F | E9: =+'Tarifario completo'!F9 -> 300 M | F9: =+G9/1.21 -> 16528.926 | G9: =+'Tarifario completo'!I9 -> 20000 | H9: =+I9/1.21 -> 35423.373 | I9: =+'Tarifario completo'!L9 -> 42862.281
B10: =+'Tarifario completo'!B10 -> WORKER F151 | C10: =+'Tarifario completo'!C10 -> S | D10: =+'Tarifario completo'!E10 -> F | E10: =+'Tarifario completo'!F10 -> 200 M | F10: =+G10/1.21 -> 16528.926 | G10: =+'Tarifario completo'!I10 -> 20000 | H10: =+I10/1.21 -> 38645.144 | I10: =+'Tarifario completo'!L10 -> 46760.624
B11: =+'Tarifario completo'!B11 -> MAX F161 (NUEVO) | C11: =+'Tarifario completo'!C11 -> S | D11: =+'Tarifario completo'!E11 -> F | E11: =+'Tarifario completo'!F11 -> 1000 M | F11: =+G11/1.21 -> 16528.926 | G11: =+'Tarifario completo'!I11 -> 20000 | H11: =+I11/1.21 -> 46146.566 | I11: =+'Tarifario completo'!L11 -> 55837.344
B12: =+'Tarifario completo'!B12 -> SistaFLEX (domicilio adicional) | H12: =+I12/1.21 -> 11982.512 | I12: =+'Tarifario completo'!L12 -> 14498.84
B13: =+'Tarifario completo'!B13 -> ANTINA PLAY + | H13: =+I13/1.21 -> 16438.017 | I13: =+'Tarifario completo'!L13 -> 19890
B14: =+'Tarifario completo'!B14 -> Básico + Cine | H14: =+I14/1.21 -> 37975.207 | I14: =+'Tarifario completo'!L14 -> 45950
B15: =+'Tarifario completo'!B15 -> Pack Fútbol (Antina) | H15: =+I15/1.21 -> 24380.165 | I15: =+'Tarifario completo'!L15 -> 29500
B16: =+'Tarifario completo'!B16 -> DGO Full | H16: =+I16/1.21 -> 28966.942 | I16: =+'Tarifario completo'!L16 -> 35050
B17: =+'Tarifario completo'!B17 -> DGo Fútbol total (Full + Dsports + Amazon + Fútbol) NUEVO | H17: =+I17/1.21 -> 32479.339 | I17: =+'Tarifario completo'!L17 -> 39300
B18: =+'Tarifario completo'!B18 -> Pack Fútbol (DGo) | H18: =+I18/1.21 -> 21165.289 | I18: =+'Tarifario completo'!L18 -> 25610
B19: =+'Tarifario completo'!B19 -> PARAMOUNT + (Dgo) | H19: =+I19/1.21 -> 7549.5868 | I19: =+'Tarifario completo'!L19 -> 9135
B20: =+'Tarifario completo'!B20 -> UNIVERSAL (DGo) | H20: =+I20/1.21 -> 12495.868 | I20: =+'Tarifario completo'!L20 -> 15120
B21: =+'Tarifario completo'!B21 -> GIGARED Básico | H21: =+I21/1.21 -> 10826.446 | I21: =+'Tarifario completo'!L21 -> 13100
B22: =+'Tarifario completo'!B22 -> Pack Fútbol (Gigared) | H22: =+I22/1.21 -> 21165.289 | I22: =+'Tarifario completo'!L22 -> 25610
B23: =+'Tarifario completo'!B23 -> LINEA VIP 55-011 | H23: =+I23/1.21 -> 17728.414 | I23: =+'Tarifario completo'!L23 -> 21451.381
B24: =+'Tarifario completo'!B24 -> LINEA VIP 56-221 | C24: =+'Tarifario completo'!C24 -> 0 | D24: =+'Tarifario completo'!E24 -> 0 | E24: =+'Tarifario completo'!F24 -> 0 | F24: =+G24/1.21 -> 0 | G24: =+'Tarifario completo'!I24 -> 0 | H24: =+I24/1.21 -> 8414.0554 | I24: =+'Tarifario completo'!L24 -> 10181.007
B25: =+'Tarifario completo'!B25 -> PABXIP VIRTUAL.BASICA (****) | C25: =+'Tarifario completo'!C25 -> 0 | D25: =+'Tarifario completo'!E25 -> 0 | E25: =+'Tarifario completo'!F25 -> 0 | F25: =+G25/1.21 -> 177272.73 | G25: =+'Tarifario completo'!I25 -> 214500 | H25: =+I25/1.21 -> 31969.704 | I25: =+'Tarifario completo'!L25 -> 38683.342
B26: =+'Tarifario completo'!B26 -> Línea Adicional a PABXIP | C26: =+'Tarifario completo'!C26 -> 0 | D26: =+'Tarifario completo'!E26 -> 0 | E26: =+'Tarifario completo'!F26 -> 0 | F26: =+G26/1.21 -> 0 | G26: =+'Tarifario completo'!I26 -> 0 | H26: =+I26/1.21 -> 6393.9408 | I26: =+'Tarifario completo'!L26 -> 7736.6684
B27: =+'Tarifario completo'!B27 -> Internos adicionales a PABXIP | C27: =+'Tarifario completo'!C27 -> 0 | D27: =+'Tarifario completo'!E27 -> 0 | E27: =+'Tarifario completo'!F27 -> 0 | F27: =+G27/1.21 -> 0 | G27: =+'Tarifario completo'!I27 -> 0 | H27: =+I27/1.21 -> 3196.9704 | I27: =+'Tarifario completo'!L27 -> 3868.3342
B28: =+'Tarifario completo'!B28 -> SPRINT Banda 74 | C28: =+'Tarifario completo'!C28 -> A | D28: =+'Tarifario completo'!E28 -> R | E28: =+'Tarifario completo'!F28 -> 6/3 M | F28: =+G28/1.21 -> 41322.314 | G28: =+'Tarifario completo'!I28 -> 50000 | H28: =+I28/1.21 -> 37912.89 | I28: =+'Tarifario completo'!L28 -> 45874.597
B29: =+'Tarifario completo'!B29 -> SPRINT Banda 77 (*) | C29: =+'Tarifario completo'!C29 -> A | D29: =+'Tarifario completo'!E29 -> R | E29: =+'Tarifario completo'!F29 -> 10/5 M | F29: =+G29/1.21 -> 41322.314 | G29: =+'Tarifario completo'!I29 -> 50000 | H29: =+I29/1.21 -> 42711.729 | I29: =+'Tarifario completo'!L29 -> 51681.192
B30: =+'Tarifario completo'!B37 -> Cableado por dispositivo HASTA 10 metros | F30: =+G30/1.21 -> 33057.851 | G30: =+'Tarifario completo'!I37 -> 40000 | H30: =+I30/1.21 -> 0 | I30: =+'Tarifario completo'!L37 -> 0
B31: =+'Tarifario completo'!B38 -> Cableado METRO ADICIONAL | F31: =+G31/1.21 -> 3305.7851 | G31: =+'Tarifario completo'!I38 -> 4000
B32: =+'Tarifario completo'!B39 -> Tareas a domicilio (precio por hora) | F32: =+G32/1.21 -> 33057.851 | G32: =+'Tarifario completo'!I39 -> 40000 | H32: =+I32/1.21 -> 0 | I32: =+'Tarifario completo'!L39 -> 0
B33: =+'Tarifario completo'!B40 -> Traslado de Servicio RADIO | F33: =+G33/1.21 -> 24793.388 | G33: =+'Tarifario completo'!I40 -> 30000 | H33: =+I33/1.21 -> 0 | I33: =+'Tarifario completo'!L40 -> 0
B34: =+'Tarifario completo'!B41 -> Traslado de Servicio FIBRA | F34: =+G34/1.21 -> 13636.364 | G34: =+'Tarifario completo'!I41 -> 16500 | H34: =+I34/1.21 -> 0 | I34: =+'Tarifario completo'!L41 -> 0
B35: =+'Tarifario completo'!B42 -> ROUTER - Configuracion en oficina | F35: =+G35/1.21 -> 13636.364 | G35: =+'Tarifario completo'!I42 -> 16500 | H35: =+I35/1.21 -> 0 | I35: =+'Tarifario completo'!L42 -> 0
B36: =+'Tarifario completo'!B43 -> ROUTER - Configuracion, instalacion en domicilio y puesta en servicio | F36: =+G36/1.21 -> 33057.851 | G36: =+'Tarifario completo'!I43 -> 40000 | H36: =+I36/1.21 -> 0 | I36: =+'Tarifario completo'!L43 -> 0
B37: =+'Tarifario completo'!B44 -> Reactivación del Servicio (**) | F37: =+G37/1.21 -> 3719.0083 | G37: =+'Tarifario completo'!I44 -> 4500
B38: =+'Tarifario completo'!B45 -> Reconexión del Servicio (***) | F38: =+G38/1.21 -> 10743.802 | G38: =+'Tarifario completo'!I45 -> 13000
B39: =+'Tarifario completo'!B47 -> Direccion IP Publica Fija | G39: =+'Tarifario completo'!I47 -> 0 | H39: =+I39/1.21 -> 35858.663 | I39: =+'Tarifario completo'!L47 -> 43388.982
B41: (*) BANDA 77 SÓLO para zona ARCO IRIS | H41: S = Simétrico
B42: (**) Cliente que reactiva un servicio luego de un corte por falta de pago | H42: A = Asimétrico
...

Sheet Linea VIP - Tarifas Web
B2: Sista s.a. - LINEA VIP | J2: =+'Tarifario completo'!L2 -> 46266
B3: Nombre | C3: Clientes | D3: Número Local | E3: Cargo Inicial | F3: Abono Mensual | G3: Minutos Locales Incluidos | H3: Llamadas a Celulares | I3: Precio de los Minutos Excedentes
I4: Destino Local | J4: Destino Nacional
B5: Linea VIP R11 | C5: Radio | D5: AMBA 011 | E5: 800 | F5: =+'Tarifario completo'!L23 -> 21451.381 | G5: 500 | H5: =+'Tarifario completo'!$L$48 -> 239.63344 | I5: =+'Tarifario completo'!$L$49 -> 30.04026 | J5: =+'Tarifario completo'!$L$50 -> 29.850533
B6: Linea VIP R221 | C6: Radio | D6: LP 0221 | E6: 800 | F6: =+'Tarifario completo'!L24 -> 10181.007 | G6: 500 | I6: =+'Tarifario completo'!$L$49 -> 30.04026
B7: Linea VIP 11 | C7: Fibra | D7: AMBA 011 | E7: -- | F7: =+F5 -> 21451.381 | G7: 500 | I7: =+'Tarifario completo'!$L$49 -> 30.04026
B8: Linea VIP 221 | C8: Fibra | D8: LP 0221 | E8: -- | F8: =+F6 -> 10181.007 | G8: 500 | I8: =+'Tarifario completo'!$L$49 -> 30.04026
J9: =+'Tarifario completo'!F2 -> 26.09
B10: Aparato telefonico (Opcional): Ver ofertas de vitrina
B12: El precio de las llamadas internacionales se expresa en U$S según el Cuadro Tarifario Internacional vigente
G13: www.sista.ar/internacional
B14: Valores en Pesos ($)
B15: Incluye IVA, del 21 %
B17: Para cada abonado de fibra, se puede incorporar hasta 2 líneas VIP 11 o VIP 221, las dos iguales o una y una
B18: Para cada abonado de ATA se puede incorporar una línea VIP R11 o VIP R221
A20: Copiar rango A1:J18, pegarlo en Word, guardarlo como "página web filtrada" al resultante en htm renombrarlo como "index.php" (así en minúsculas). Configurar Diseño de Página "HORIZONTAL" Revisar tamaño de tabla, y si hace falta achicar la fuente del texto. Al guardar, aparece una ventana, responder que "sí"

Sheet Internacional
B2: Precio del minuto de llamadas Internacionales
D3: Vigencia a partir del: | E3: 46174
B4: Prefijo | C4: Destino | D4: Fijo / Móvil | E4: Precio [U$S]
B5: 0093 | C5: AFGANISTAN | D5: Fijo | E5: 0.5 | G5: Copiar las 4 columnas, pegar en Word como "texto", agregarle las tabulaciones y guardar como "página web filtrada" y nombre "index.php"
B6: 009370 | C6: AFGANISTAN | D6: Movil | E6: 0.5
B7: 001907 | C7: ALASKA | D7: Fijo | E7: 0.1
B8: 001907209 | C8: ALASKA | D8: Movil | E8: 0.1
B9: 001907223 | C9: ALASKA | D9: Movil | E9: 0.1 | G9: Estos precios son los de Metrotel, con un incremento del 30 % y el iva del 21 %
B10: 001907227 | C10: ALASKA | D10: Movil | E10: 0.1
B11: 001907229 | C11: ALASKA | D11: Movil | E11: 0.1
B12: 001907230 | C12: ALASKA | D12: Movil | E12: 0.1
B13: 001907232 | C13: ALASKA | D13: Movil | E13: 0.1
B14: 001907240 | C14: ALASKA | D14: Movil | E14: 0.1
B15: 001907242 | C15: ALASKA | D15: Movil | E15: 0.1
B16: 001907244 | C16: ALASKA | D16: Movil | E16: 0.1
B17: 001907250 | C17: ALASKA | D17: Movil | E17: 0.1
B18: 001907252 | C18: ALASKA | D18: Movil | E18: 0.1
B19: 001907253 | C19: ALASKA | D19: Movil | E19: 0.1
B20: 001907254 | C20: ALASKA | D20: Movil | E20: 0.1
B21: 001907255 | C21: ALASKA | D21: Movil | E21: 0.1
... B3277: 0026391 | C3277: ZIMBABWE ECONET | D3277: Fijo | E3277: 0.5
